<?xml version="1.0" encoding="utf-8"?>
<robot
  name="corn3">
  <link
    name="base_link">
    <inertial>
      <origin
        xyz="0.0020787 0.45793 2.058"
        rpy="0 0 0" />
      <mass
        value="40068" />
      <inertia
        ixx="302500"
        ixy="-69.138"
        ixz="321.56"
        iyy="355850"
        iyz="-1374.3"
        izz="172590" />
    </inertial>
    <visual>
      <origin
        xyz="0 0 0"
        rpy="0 0 0" />
      <geometry>
        <mesh
          filename="package://sim01_urdf/meshes/base_link.STL" />
      </geometry>
      <material
        name="">
        <color
          rgba="0.79216 0.81961 0.93333 1" />
      </material>
    </visual>
    <collision>
      <origin
        xyz="0 0 0"
        rpy="0 0 0" />
      <geometry>
        <mesh
          filename="package://sim01_urdf/meshes/base_link.STL" />
      </geometry>
    </collision>
  </link>
  <link
    name="left_front_wheel_link0">
    <inertial>
      <origin
        xyz="-0.3271 0.14034 0.020054"
        rpy="0 0 0" />
      <mass
        value="950.62" />
      <inertia
        ixx="388.87"
        ixy="-2.1869E-09"
        ixz="0.001334"
        iyy="218.49"
        iyz="-1.5235E-09"
        izz="218.49" />
    </inertial>
    <visual>
      <origin
        xyz="0 0 0"
        rpy="0 0 0" />
      <geometry>
        <mesh
          filename="package://sim01_urdf/meshes/left_front_wheel_link0.STL" />
      </geometry>
      <material
        name="">
        <color
          rgba="0.79216 0.81961 0.93333 1" />
      </material>
    </visual>
    <collision>
      <origin
        xyz="0 0 0"
        rpy="0 0 0" />
      <geometry>
        <mesh
          filename="package://sim01_urdf/meshes/left_front_wheel_link0.STL" />
      </geometry>
    </collision>
  </link>
  <joint
    name="left_front_wheel_joint0"
    type="continuous">
    <origin
      xyz="2.767 -3.5054 -1.1624"
      rpy="-1.5708 0 3.1416" />
    <parent
      link="base_link" />
    <child
      link="left_front_wheel_link0" />
    <axis
      xyz="1 0 0" />
  </joint>
  <link
    name="right_front_wheel_link1">
    <inertial>
      <origin
        xyz="-0.3271 0.14034 0.020054"
        rpy="0 0 0" />
      <mass
        value="950.62" />
      <inertia
        ixx="388.87"
        ixy="-2.1873E-09"
        ixz="0.001334"
        iyy="218.49"
        iyz="-1.5235E-09"
        izz="218.49" />
    </inertial>
    <visual>
      <origin
        xyz="0 0 0"
        rpy="0 0 0" />
      <geometry>
        <mesh
          filename="package://sim01_urdf/meshes/right_front_wheel_link1.STL" />
      </geometry>
      <material
        name="">
        <color
          rgba="0.79216 0.81961 0.93333 1" />
      </material>
    </visual>
    <collision>
      <origin
        xyz="0 0 0"
        rpy="0 0 0" />
      <geometry>
        <mesh
          filename="package://sim01_urdf/meshes/right_front_wheel_link1.STL" />
      </geometry>
    </collision>
  </link>
  <joint
    name="right_front_wheel_joint1"
    type="continuous">
    <origin
      xyz="-2.767 -3.5054 -1.4431"
      rpy="1.5708 0 0" />
    <parent
      link="base_link" />
    <child
      link="right_front_wheel_link1" />
    <axis
      xyz="1 0 0" />
  </joint>
  <link
    name="right_rear_wheel_link2">
    <inertial>
      <origin
        xyz="-0.3271 0.14034 0.020054"
        rpy="0 0 0" />
      <mass
        value="950.62" />
      <inertia
        ixx="388.87"
        ixy="-2.1873E-09"
        ixz="0.001334"
        iyy="218.49"
        iyz="-1.5235E-09"
        izz="218.49" />
    </inertial>
    <visual>
      <origin
        xyz="0 0 0"
        rpy="0 0 0" />
      <geometry>
        <mesh
          filename="package://sim01_urdf/meshes/right_rear_wheel_link2.STL" />
      </geometry>
      <material
        name="">
        <color
          rgba="0.79216 0.81961 0.93333 1" />
      </material>
    </visual>
    <collision>
      <origin
        xyz="0 0 0"
        rpy="0 0 0" />
      <geometry>
        <mesh
          filename="package://sim01_urdf/meshes/right_rear_wheel_link2.STL" />
      </geometry>
    </collision>
  </link>
  <joint
    name="right_rear_wheel_joint2"
    type="continuous">
    <origin
      xyz="-2.767 2.3546 -1.4431"
      rpy="1.5708 0 0" />
    <parent
      link="base_link" />
    <child
      link="right_rear_wheel_link2" />
    <axis
      xyz="1 0 0" />
  </joint>
  <link
    name="left_rear_wheel_link3">
    <inertial>
      <origin
        xyz="-0.3271 0.14034 0.020054"
        rpy="0 0 0" />
      <mass
        value="950.62" />
      <inertia
        ixx="388.87"
        ixy="-2.1869E-09"
        ixz="0.001334"
        iyy="218.49"
        iyz="-1.5235E-09"
        izz="218.49" />
    </inertial>
    <visual>
      <origin
        xyz="0 0 0"
        rpy="0 0 0" />
      <geometry>
        <mesh
          filename="package://sim01_urdf/meshes/left_rear_wheel_link3.STL" />
      </geometry>
      <material
        name="">
        <color
          rgba="0.79216 0.81961 0.93333 1" />
      </material>
    </visual>
    <collision>
      <origin
        xyz="0 0 0"
        rpy="0 0 0" />
      <geometry>
        <mesh
          filename="package://sim01_urdf/meshes/left_rear_wheel_link3.STL" />
      </geometry>
    </collision>
  </link>
  <joint
    name="left_rear_wheel_joint3"
    type="continuous">
    <origin
      xyz="2.767 2.3546 -1.1624"
      rpy="-1.5708 0 3.1416" />
    <parent
      link="base_link" />
    <child
      link="left_rear_wheel_link3" />
    <axis
      xyz="1 0 0" />
  </joint>
  <link
    name="laser_link">
    <inertial>
      <origin
        xyz="-0.00098912 -0.21034 -0.0064035"
        rpy="0 0 0" />
      <mass
        value="141.89" />
      <inertia
        ixx="4.3307"
        ixy="-0.014198"
        ixz="-0.1636"
        iyy="6.8801"
        iyz="-0.022421"
        izz="4.3567" />
    </inertial>
    <visual>
      <origin
        xyz="0 0 0"
        rpy="0 0 0" />
      <geometry>
        <mesh
          filename="package://sim01_urdf/meshes/laser_link.STL" />
      </geometry>
      <material
        name="">
        <color
          rgba="0.79216 0.81961 0.93333 1" />
      </material>
    </visual>
    <collision>
      <origin
        xyz="0 0 0"
        rpy="0 0 0" />
      <geometry>
        <mesh
          filename="package://sim01_urdf/meshes/laser_link.STL" />
      </geometry>
    </collision>
  </link>
  <joint
    name="laser_joint"
    type="fixed">
    <origin
      xyz="0.005493 -2.8923 3.7226"
      rpy="1.5718 -0.0036179 2.3184" />
    <parent
      link="base_link" />
    <child
      link="laser_link" />
    <axis
      xyz="0 0 0" />
  </joint>
</robot>