<?xml version="1.0" encoding="utf-8"?>
<robot
  name="corn_harvester">
  <link
    name="base_link">
    <inertial>
      <origin
        xyz="2.058 0.0020787 0.45793"
        rpy="0 0 0" />
      <mass
        value="40068" />
      <inertia
        ixx="172590"
        ixy="321.56"
        ixz="-1374.3"
        iyy="302500"
        iyz="-69.138"
        izz="355850" />
    </inertial>
    <visual>
      <origin
        xyz="0 0 0"
        rpy="0 0 0" />
      <geometry>
        <mesh
          filename="package://sim01_urdf/meshes/base_link.STL" />
      </geometry>
      <material
        name="">
        <color
          rgba="0.79216 0.81961 0.93333 1" />
      </material>
    </visual>
    <collision>
      <origin
        xyz="0 0 0"
        rpy="0 0 0" />
      <geometry>
        <mesh
          filename="package://sim01_urdf/meshes/base_link.STL" />
      </geometry>
    </collision>
  </link>
  <link
    name="left_front_wheel_link0">
    <inertial>
      <origin
        xyz="-0.3271 0.14034 0.020054"
        rpy="0 0 0" />
      <mass
        value="950.62" />
      <inertia
        ixx="388.87"
        ixy="-2.1974E-09"
        ixz="0.001334"
        iyy="218.49"
        iyz="-1.5235E-09"
        izz="218.49" />
    </inertial>
    <visual>
      <origin
        xyz="0 0 0"
        rpy="0 0 0" />
      <geometry>
        <mesh
          filename="package://sim01_urdf/meshes/left_front_wheel_link0.STL" />
      </geometry>
      <material
        name="">
        <color
          rgba="0.79216 0.81961 0.93333 1" />
      </material>
    </visual>
    <collision>
      <origin
        xyz="0 0 0"
        rpy="0 0 0" />
      <geometry>
        <mesh
          filename="package://sim01_urdf/meshes/left_front_wheel_link0.STL" />
      </geometry>
    </collision>
  </link>
  <joint
    name="left_front_wheel_joint0"
    type="continuous">
    <origin
      xyz="3.4954 1.1624 2.767"
      rpy="0 1.5708 0" />
    <parent
      link="base_link" />
    <child
      link="left_front_wheel_link0" />
    <axis
      xyz="0 1 0" />
  </joint>
  <link
    name="right_front_wheel_link1">
    <inertial>
      <origin
        xyz="-0.3271 0.14034 0.020054"
        rpy="0 0 0" />
      <mass
        value="950.62" />
      <inertia
        ixx="388.87"
        ixy="-2.1856E-09"
        ixz="0.001334"
        iyy="218.49"
        iyz="-1.5235E-09"
        izz="218.49" />
    </inertial>
    <visual>
      <origin
        xyz="0 0 0"
        rpy="0 0 0" />
      <geometry>
        <mesh
          filename="package://sim01_urdf/meshes/right_front_wheel_link1.STL" />
      </geometry>
      <material
        name="">
        <color
          rgba="0.79216 0.81961 0.93333 1" />
      </material>
    </visual>
    <collision>
      <origin
        xyz="0 0 0"
        rpy="0 0 0" />
      <geometry>
        <mesh
          filename="package://sim01_urdf/meshes/right_front_wheel_link1.STL" />
      </geometry>
    </collision>
  </link>
  <joint
    name="right_front_wheel_joint1"
    type="continuous">
    <origin
      xyz="3.4954 1.4431 -2.767"
      rpy="0 -1.5708 0" />
    <parent
      link="base_link" />
    <child
      link="right_front_wheel_link1" />
    <axis
      xyz="0 1 0" />
  </joint>
  <link
    name="right_rear_wheel_link2">
    <inertial>
      <origin
        xyz="-0.3271 0.14034 0.020054"
        rpy="0 0 0" />
      <mass
        value="950.62" />
      <inertia
        ixx="388.87"
        ixy="-2.1856E-09"
        ixz="0.001334"
        iyy="218.49"
        iyz="-1.5235E-09"
        izz="218.49" />
    </inertial>
    <visual>
      <origin
        xyz="0 0 0"
        rpy="0 0 0" />
      <geometry>
        <mesh
          filename="package://sim01_urdf/meshes/right_rear_wheel_link2.STL" />
      </geometry>
      <material
        name="">
        <color
          rgba="0.79216 0.81961 0.93333 1" />
      </material>
    </visual>
    <collision>
      <origin
        xyz="0 0 0"
        rpy="0 0 0" />
      <geometry>
        <mesh
          filename="package://sim01_urdf/meshes/right_rear_wheel_link2.STL" />
      </geometry>
    </collision>
  </link>
  <joint
    name="right_rear_wheel_joint2"
    type="continuous">
    <origin
      xyz="-2.3646 1.4431 -2.767"
      rpy="0 -1.5708 0" />
    <parent
      link="base_link" />
    <child
      link="right_rear_wheel_link2" />
    <axis
      xyz="0 1 0" />
  </joint>
  <link
    name="left_rear_wheel_link3">
    <inertial>
      <origin
        xyz="-0.3271 0.14034 0.020054"
        rpy="0 0 0" />
      <mass
        value="950.62" />
      <inertia
        ixx="388.87"
        ixy="-2.1974E-09"
        ixz="0.001334"
        iyy="218.49"
        iyz="-1.5235E-09"
        izz="218.49" />
    </inertial>
    <visual>
      <origin
        xyz="0 0 0"
        rpy="0 0 0" />
      <geometry>
        <mesh
          filename="package://sim01_urdf/meshes/left_rear_wheel_link3.STL" />
      </geometry>
      <material
        name="">
        <color
          rgba="0.79216 0.81961 0.93333 1" />
      </material>
    </visual>
    <collision>
      <origin
        xyz="0 0 0"
        rpy="0 0 0" />
      <geometry>
        <mesh
          filename="package://sim01_urdf/meshes/left_rear_wheel_link3.STL" />
      </geometry>
    </collision>
  </link>
  <joint
    name="left_rear_wheel_joint3"
    type="continuous">
    <origin
      xyz="-2.3646 1.1624 2.767"
      rpy="0 1.5708 0" />
    <parent
      link="base_link" />
    <child
      link="left_rear_wheel_link3" />
    <axis
      xyz="0 1 0" />
  </joint>
  <link
    name="laser_link">
    <inertial>
      <origin
        xyz="-0.00099017 -0.21034 -0.0064028"
        rpy="0 0 0" />
      <mass
        value="141.89" />
      <inertia
        ixx="4.3307"
        ixy="-0.014198"
        ixz="-0.1636"
        iyy="6.8801"
        iyz="-0.022422"
        izz="4.3567" />
    </inertial>
    <visual>
      <origin
        xyz="0 0 0"
        rpy="0 0 0" />
      <geometry>
        <mesh
          filename="package://sim01_urdf/meshes/laser_link.STL" />
      </geometry>
      <material
        name="">
        <color
          rgba="0.79216 0.81961 0.93333 1" />
      </material>
    </visual>
    <collision>
      <origin
        xyz="0 0 0"
        rpy="0 0 0" />
      <geometry>
        <mesh
          filename="package://sim01_urdf/meshes/laser_link.STL" />
      </geometry>
    </collision>
  </link>
  <joint
    name="laser_joint"
    type="fixed">
    <origin
      xyz="2.8823 -3.7226 0.005493"
      rpy="0.0043263 0.7476 -3.1367" />
    <parent
      link="base_link" />
    <child
      link="laser_link" />
    <axis
      xyz="0 0 0" />
  </joint>
</robot>